Exception on /receiveMessage [POST]
Traceback (most recent call last):
  File "/home/renner/special/mac0499-prototype/venv/lib/python3.12/site-packages/flask/app.py", line 1473, in wsgi_app
    response = self.full_dispatch_request()
               ^^^^^^^^^^^^^^^^^^^^^^^^^^^^
  File "/home/renner/special/mac0499-prototype/venv/lib/python3.12/site-packages/flask/app.py", line 882, in full_dispatch_request
    rv = self.handle_user_exception(e)
         ^^^^^^^^^^^^^^^^^^^^^^^^^^^^^
  File "/home/renner/special/mac0499-prototype/venv/lib/python3.12/site-packages/flask/app.py", line 880, in full_dispatch_request
    rv = self.dispatch_request()
         ^^^^^^^^^^^^^^^^^^^^^^^
  File "/home/renner/special/mac0499-prototype/venv/lib/python3.12/site-packages/flask/app.py", line 865, in dispatch_request
    return self.ensure_sync(self.view_functions[rule.endpoint])(**view_args)  # type: ignore[no-any-return]
           ^^^^^^^^^^^^^^^^^^^^^^^^^^^^^^^^^^^^^^^^^^^^^^^^^^^^^^^^^^^^^^^^^
  File "/home/renner/special/mac0499-prototype/src/endpoints.py", line 31, in receiveMessage
    receivedDate: datetime.now()
    ^^^^^^^^^^^^
NameError: name 'receivedDate' is not defined
Exception on /receiveMessage [POST]
Traceback (most recent call last):
  File "/home/renner/special/mac0499-prototype/venv/lib/python3.12/site-packages/flask/app.py", line 1473, in wsgi_app
    response = self.full_dispatch_request()
               ^^^^^^^^^^^^^^^^^^^^^^^^^^^^
  File "/home/renner/special/mac0499-prototype/venv/lib/python3.12/site-packages/flask/app.py", line 882, in full_dispatch_request
    rv = self.handle_user_exception(e)
         ^^^^^^^^^^^^^^^^^^^^^^^^^^^^^
  File "/home/renner/special/mac0499-prototype/venv/lib/python3.12/site-packages/flask/app.py", line 880, in full_dispatch_request
    rv = self.dispatch_request()
         ^^^^^^^^^^^^^^^^^^^^^^^
  File "/home/renner/special/mac0499-prototype/venv/lib/python3.12/site-packages/flask/app.py", line 865, in dispatch_request
    return self.ensure_sync(self.view_functions[rule.endpoint])(**view_args)  # type: ignore[no-any-return]
           ^^^^^^^^^^^^^^^^^^^^^^^^^^^^^^^^^^^^^^^^^^^^^^^^^^^^^^^^^^^^^^^^^
  File "/home/renner/special/mac0499-prototype/src/endpoints.py", line 31, in receiveMessage
    "receivedDate": datetime.now()
                    ^^^^^^^^
NameError: name 'datetime' is not defined. Did you forget to import 'datetime'
Exception on /receiveMessage [POST]
Traceback (most recent call last):
  File "/home/renner/special/mac0499-prototype/venv/lib/python3.12/site-packages/flask/app.py", line 1473, in wsgi_app
    response = self.full_dispatch_request()
               ^^^^^^^^^^^^^^^^^^^^^^^^^^^^
  File "/home/renner/special/mac0499-prototype/venv/lib/python3.12/site-packages/flask/app.py", line 882, in full_dispatch_request
    rv = self.handle_user_exception(e)
         ^^^^^^^^^^^^^^^^^^^^^^^^^^^^^
  File "/home/renner/special/mac0499-prototype/venv/lib/python3.12/site-packages/flask/app.py", line 880, in full_dispatch_request
    rv = self.dispatch_request()
         ^^^^^^^^^^^^^^^^^^^^^^^
  File "/home/renner/special/mac0499-prototype/venv/lib/python3.12/site-packages/flask/app.py", line 865, in dispatch_request
    return self.ensure_sync(self.view_functions[rule.endpoint])(**view_args)  # type: ignore[no-any-return]
           ^^^^^^^^^^^^^^^^^^^^^^^^^^^^^^^^^^^^^^^^^^^^^^^^^^^^^^^^^^^^^^^^^
  File "/home/renner/special/mac0499-prototype/src/endpoints.py", line 32, in receiveMessage
    "receivedDate": datetime.now()
                    ^^^^^^^^^^^^
AttributeError: module 'datetime' has no attribute 'now'
Exception on /receiveMessage [POST]
Traceback (most recent call last):
  File "/home/renner/special/mac0499-prototype/venv/lib/python3.12/site-packages/flask/app.py", line 1473, in wsgi_app
    response = self.full_dispatch_request()
               ^^^^^^^^^^^^^^^^^^^^^^^^^^^^
  File "/home/renner/special/mac0499-prototype/venv/lib/python3.12/site-packages/flask/app.py", line 882, in full_dispatch_request
    rv = self.handle_user_exception(e)
         ^^^^^^^^^^^^^^^^^^^^^^^^^^^^^
  File "/home/renner/special/mac0499-prototype/venv/lib/python3.12/site-packages/flask/app.py", line 880, in full_dispatch_request
    rv = self.dispatch_request()
         ^^^^^^^^^^^^^^^^^^^^^^^
  File "/home/renner/special/mac0499-prototype/venv/lib/python3.12/site-packages/flask/app.py", line 865, in dispatch_request
    return self.ensure_sync(self.view_functions[rule.endpoint])(**view_args)  # type: ignore[no-any-return]
           ^^^^^^^^^^^^^^^^^^^^^^^^^^^^^^^^^^^^^^^^^^^^^^^^^^^^^^^^^^^^^^^^^
  File "/home/renner/special/mac0499-prototype/src/endpoints.py", line 37, in receiveMessage
    f.write(json.dumps(message) + "\n")
            ^^^^^^^^^^^^^^^^^^^
  File "/usr/lib/python3.12/json/__init__.py", line 231, in dumps
    return _default_encoder.encode(obj)
           ^^^^^^^^^^^^^^^^^^^^^^^^^^^^
  File "/usr/lib/python3.12/json/encoder.py", line 200, in encode
    chunks = self.iterencode(o, _one_shot=True)
             ^^^^^^^^^^^^^^^^^^^^^^^^^^^^^^^^^^
  File "/usr/lib/python3.12/json/encoder.py", line 258, in iterencode
    return _iterencode(o, 0)
           ^^^^^^^^^^^^^^^^^
  File "/usr/lib/python3.12/json/encoder.py", line 180, in default
    raise TypeError(f'Object of type {o.__class__.__name__} '
TypeError: Object of type datetime is not JSON serializable
Exception on /sendMessage [POST]
Traceback (most recent call last):
  File "/home/renner/special/mac0499-prototype/venv/lib/python3.12/site-packages/flask/app.py", line 1473, in wsgi_app
    response = self.full_dispatch_request()
               ^^^^^^^^^^^^^^^^^^^^^^^^^^^^
  File "/home/renner/special/mac0499-prototype/venv/lib/python3.12/site-packages/flask/app.py", line 882, in full_dispatch_request
    rv = self.handle_user_exception(e)
         ^^^^^^^^^^^^^^^^^^^^^^^^^^^^^
  File "/home/renner/special/mac0499-prototype/venv/lib/python3.12/site-packages/flask/app.py", line 880, in full_dispatch_request
    rv = self.dispatch_request()
         ^^^^^^^^^^^^^^^^^^^^^^^
  File "/home/renner/special/mac0499-prototype/venv/lib/python3.12/site-packages/flask/app.py", line 865, in dispatch_request
    return self.ensure_sync(self.view_functions[rule.endpoint])(**view_args)  # type: ignore[no-any-return]
           ^^^^^^^^^^^^^^^^^^^^^^^^^^^^^^^^^^^^^^^^^^^^^^^^^^^^^^^^^^^^^^^^^
  File "/home/renner/special/mac0499-prototype/src/endpoints.py", line 66, in sendMessage
    decodedMessage = json.loads(flask.request.form.get("message"))
                     ^^^^^^^^^^^^^^^^^^^^^^^^^^^^^^^^^^^^^^^^^^^^^
  File "/usr/lib/python3.12/json/__init__.py", line 339, in loads
    raise TypeError(f'the JSON object must be str, bytes or bytearray, '
TypeError: the JSON object must be str, bytes or bytearray, not NoneType
Exception on /sendMessage [POST]
Traceback (most recent call last):
  File "/home/renner/special/mac0499-prototype/venv/lib/python3.12/site-packages/flask/app.py", line 1473, in wsgi_app
    response = self.full_dispatch_request()
               ^^^^^^^^^^^^^^^^^^^^^^^^^^^^
  File "/home/renner/special/mac0499-prototype/venv/lib/python3.12/site-packages/flask/app.py", line 882, in full_dispatch_request
    rv = self.handle_user_exception(e)
         ^^^^^^^^^^^^^^^^^^^^^^^^^^^^^
  File "/home/renner/special/mac0499-prototype/venv/lib/python3.12/site-packages/flask/app.py", line 880, in full_dispatch_request
    rv = self.dispatch_request()
         ^^^^^^^^^^^^^^^^^^^^^^^
  File "/home/renner/special/mac0499-prototype/venv/lib/python3.12/site-packages/flask/app.py", line 865, in dispatch_request
    return self.ensure_sync(self.view_functions[rule.endpoint])(**view_args)  # type: ignore[no-any-return]
           ^^^^^^^^^^^^^^^^^^^^^^^^^^^^^^^^^^^^^^^^^^^^^^^^^^^^^^^^^^^^^^^^^
  File "/home/renner/special/mac0499-prototype/src/endpoints.py", line 66, in sendMessage
    decodedMessage = json.loads(flask.request.form.get("message"))
                     ^^^^^^^^^^^^^^^^^^^^^^^^^^^^^^^^^^^^^^^^^^^^^
  File "/usr/lib/python3.12/json/__init__.py", line 339, in loads
    raise TypeError(f'the JSON object must be str, bytes or bytearray, '
TypeError: the JSON object must be str, bytes or bytearray, not NoneType
Exception on /sendMessage [POST]
Traceback (most recent call last):
  File "/home/renner/special/mac0499-prototype/venv/lib/python3.12/site-packages/flask/app.py", line 1473, in wsgi_app
    response = self.full_dispatch_request()
               ^^^^^^^^^^^^^^^^^^^^^^^^^^^^
  File "/home/renner/special/mac0499-prototype/venv/lib/python3.12/site-packages/flask/app.py", line 882, in full_dispatch_request
    rv = self.handle_user_exception(e)
         ^^^^^^^^^^^^^^^^^^^^^^^^^^^^^
  File "/home/renner/special/mac0499-prototype/venv/lib/python3.12/site-packages/flask/app.py", line 880, in full_dispatch_request
    rv = self.dispatch_request()
         ^^^^^^^^^^^^^^^^^^^^^^^
  File "/home/renner/special/mac0499-prototype/venv/lib/python3.12/site-packages/flask/app.py", line 865, in dispatch_request
    return self.ensure_sync(self.view_functions[rule.endpoint])(**view_args)  # type: ignore[no-any-return]
           ^^^^^^^^^^^^^^^^^^^^^^^^^^^^^^^^^^^^^^^^^^^^^^^^^^^^^^^^^^^^^^^^^
  File "/home/renner/special/mac0499-prototype/src/endpoints.py", line 66, in sendMessage
    decodedMessage = flask.request.get_json()
                     ^^^^^^^^^^^^^^^^^^^^^^^^^
  File "/usr/lib/python3.12/json/__init__.py", line 339, in loads
    raise TypeError(f'the JSON object must be str, bytes or bytearray, '
TypeError: the JSON object must be str, bytes or bytearray, not NoneType
Exception on /sendMessage [POST]
Traceback (most recent call last):
  File "/home/renner/special/mac0499-prototype/venv/lib/python3.12/site-packages/socks.py", line 787, in connect
    super(socksocket, self).connect(proxy_addr)
ConnectionRefusedError: [Errno 111] Connection refused

During handling of the above exception, another exception occurred:

Traceback (most recent call last):
  File "/home/renner/special/mac0499-prototype/venv/lib/python3.12/site-packages/urllib3/contrib/socks.py", line 110, in _new_conn
    conn = socks.create_connection(
           ^^^^^^^^^^^^^^^^^^^^^^^^
  File "/home/renner/special/mac0499-prototype/venv/lib/python3.12/site-packages/socks.py", line 209, in create_connection
    raise err
  File "/home/renner/special/mac0499-prototype/venv/lib/python3.12/site-packages/socks.py", line 199, in create_connection
    sock.connect((remote_host, remote_port))
  File "/home/renner/special/mac0499-prototype/venv/lib/python3.12/site-packages/socks.py", line 47, in wrapper
    return function(*args, **kwargs)
           ^^^^^^^^^^^^^^^^^^^^^^^^^
  File "/home/renner/special/mac0499-prototype/venv/lib/python3.12/site-packages/socks.py", line 800, in connect
    raise ProxyConnectionError(msg, error)
socks.ProxyConnectionError: Error connecting to SOCKS5 proxy localhost:5878: [Errno 111] Connection refused

During handling of the above exception, another exception occurred:

Traceback (most recent call last):
  File "/home/renner/special/mac0499-prototype/venv/lib/python3.12/site-packages/urllib3/connectionpool.py", line 789, in urlopen
    response = self._make_request(
               ^^^^^^^^^^^^^^^^^^^
  File "/home/renner/special/mac0499-prototype/venv/lib/python3.12/site-packages/urllib3/connectionpool.py", line 495, in _make_request
    conn.request(
  File "/home/renner/special/mac0499-prototype/venv/lib/python3.12/site-packages/urllib3/connection.py", line 398, in request
    self.endheaders()
  File "/usr/lib/python3.12/http/client.py", line 1331, in endheaders
    self._send_output(message_body, encode_chunked=encode_chunked)
  File "/usr/lib/python3.12/http/client.py", line 1091, in _send_output
    self.send(msg)
  File "/usr/lib/python3.12/http/client.py", line 1035, in send
    self.connect()
  File "/home/renner/special/mac0499-prototype/venv/lib/python3.12/site-packages/urllib3/connection.py", line 236, in connect
    self.sock = self._new_conn()
                ^^^^^^^^^^^^^^^^
  File "/home/renner/special/mac0499-prototype/venv/lib/python3.12/site-packages/urllib3/contrib/socks.py", line 141, in _new_conn
    raise NewConnectionError(
urllib3.exceptions.NewConnectionError: <urllib3.contrib.socks.SOCKSConnection object at 0x75237a7a0620>: Failed to establish a new connection: [Errno 111] Connection refused

The above exception was the direct cause of the following exception:

Traceback (most recent call last):
  File "/home/renner/special/mac0499-prototype/venv/lib/python3.12/site-packages/requests/adapters.py", line 667, in send
    resp = conn.urlopen(
           ^^^^^^^^^^^^^
  File "/home/renner/special/mac0499-prototype/venv/lib/python3.12/site-packages/urllib3/connectionpool.py", line 843, in urlopen
    retries = retries.increment(
              ^^^^^^^^^^^^^^^^^^
  File "/home/renner/special/mac0499-prototype/venv/lib/python3.12/site-packages/urllib3/util/retry.py", line 519, in increment
    raise MaxRetryError(_pool, url, reason) from reason  # type: ignore[arg-type]
    ^^^^^^^^^^^^^^^^^^^^^^^^^^^^^^^^^^^^^^^^^^^^^^^^^^^
urllib3.exceptions.MaxRetryError: SOCKSHTTPConnectionPool(host='mkl2b3hxadsfza2k3u554s5w6hpth2zgkakbd5ydern6h57dcvggbiyd.onion', port=80): Max retries exceeded with url: /receiveMessage (Caused by NewConnectionError('<urllib3.contrib.socks.SOCKSConnection object at 0x75237a7a0620>: Failed to establish a new connection: [Errno 111] Connection refused'))

During handling of the above exception, another exception occurred:

Traceback (most recent call last):
  File "/home/renner/special/mac0499-prototype/src/endpoints.py", line 90, in sendMessage
    response = requests.post(f"http://{destination}/receiveMessage", data={"message": packagedMessage}, proxies=proxies)
               ^^^^^^^^^^^^^^^^^^^^^^^^^^^^^^^^^^^^^^^^^^^^^^^^^^^^^^^^^^^^^^^^^^^^^^^^^^^^^^^^^^^^^^^^^^^^^^^^^^^^^^^^^
  File "/home/renner/special/mac0499-prototype/venv/lib/python3.12/site-packages/requests/api.py", line 115, in post
    return request("post", url, data=data, json=json, **kwargs)
           ^^^^^^^^^^^^^^^^^^^^^^^^^^^^^^^^^^^^^^^^^^^^^^^^^^^^
  File "/home/renner/special/mac0499-prototype/venv/lib/python3.12/site-packages/requests/api.py", line 59, in request
    return session.request(method=method, url=url, **kwargs)
           ^^^^^^^^^^^^^^^^^^^^^^^^^^^^^^^^^^^^^^^^^^^^^^^^^
  File "/home/renner/special/mac0499-prototype/venv/lib/python3.12/site-packages/requests/sessions.py", line 589, in request
    resp = self.send(prep, **send_kwargs)
           ^^^^^^^^^^^^^^^^^^^^^^^^^^^^^^
  File "/home/renner/special/mac0499-prototype/venv/lib/python3.12/site-packages/requests/sessions.py", line 703, in send
    r = adapter.send(request, **kwargs)
        ^^^^^^^^^^^^^^^^^^^^^^^^^^^^^^^
  File "/home/renner/special/mac0499-prototype/venv/lib/python3.12/site-packages/requests/adapters.py", line 700, in send
    raise ConnectionError(e, request=request)
requests.exceptions.ConnectionError: SOCKSHTTPConnectionPool(host='mkl2b3hxadsfza2k3u554s5w6hpth2zgkakbd5ydern6h57dcvggbiyd.onion', port=80): Max retries exceeded with url: /receiveMessage (Caused by NewConnectionError('<urllib3.contrib.socks.SOCKSConnection object at 0x75237a7a0620>: Failed to establish a new connection: [Errno 111] Connection refused'))

During handling of the above exception, another exception occurred:

Traceback (most recent call last):
  File "/home/renner/special/mac0499-prototype/venv/lib/python3.12/site-packages/flask/app.py", line 1473, in wsgi_app
    response = self.full_dispatch_request()
               ^^^^^^^^^^^^^^^^^^^^^^^^^^^^
  File "/home/renner/special/mac0499-prototype/venv/lib/python3.12/site-packages/flask/app.py", line 882, in full_dispatch_request
    rv = self.handle_user_exception(e)
         ^^^^^^^^^^^^^^^^^^^^^^^^^^^^^
  File "/home/renner/special/mac0499-prototype/venv/lib/python3.12/site-packages/flask/app.py", line 880, in full_dispatch_request
    rv = self.dispatch_request()
         ^^^^^^^^^^^^^^^^^^^^^^^
  File "/home/renner/special/mac0499-prototype/venv/lib/python3.12/site-packages/flask/app.py", line 865, in dispatch_request
    return self.ensure_sync(self.view_functions[rule.endpoint])(**view_args)  # type: ignore[no-any-return]
           ^^^^^^^^^^^^^^^^^^^^^^^^^^^^^^^^^^^^^^^^^^^^^^^^^^^^^^^^^^^^^^^^^
  File "/home/renner/special/mac0499-prototype/src/endpoints.py", line 105, in sendMessage
    sleep(5)
    ^^^^^
NameError: name 'sleep' is not defined
Exception on /sendMessage [POST]
Traceback (most recent call last):
  File "/home/renner/special/mac0499-prototype/venv/lib/python3.12/site-packages/socks.py", line 787, in connect
    super(socksocket, self).connect(proxy_addr)
ConnectionRefusedError: [Errno 111] Connection refused

During handling of the above exception, another exception occurred:

Traceback (most recent call last):
  File "/home/renner/special/mac0499-prototype/venv/lib/python3.12/site-packages/urllib3/contrib/socks.py", line 110, in _new_conn
    conn = socks.create_connection(
           ^^^^^^^^^^^^^^^^^^^^^^^^
  File "/home/renner/special/mac0499-prototype/venv/lib/python3.12/site-packages/socks.py", line 209, in create_connection
    raise err
  File "/home/renner/special/mac0499-prototype/venv/lib/python3.12/site-packages/socks.py", line 199, in create_connection
    sock.connect((remote_host, remote_port))
  File "/home/renner/special/mac0499-prototype/venv/lib/python3.12/site-packages/socks.py", line 47, in wrapper
    return function(*args, **kwargs)
           ^^^^^^^^^^^^^^^^^^^^^^^^^
  File "/home/renner/special/mac0499-prototype/venv/lib/python3.12/site-packages/socks.py", line 800, in connect
    raise ProxyConnectionError(msg, error)
socks.ProxyConnectionError: Error connecting to SOCKS5 proxy localhost:5878: [Errno 111] Connection refused

During handling of the above exception, another exception occurred:

Traceback (most recent call last):
  File "/home/renner/special/mac0499-prototype/venv/lib/python3.12/site-packages/urllib3/connectionpool.py", line 789, in urlopen
    response = self._make_request(
               ^^^^^^^^^^^^^^^^^^^
  File "/home/renner/special/mac0499-prototype/venv/lib/python3.12/site-packages/urllib3/connectionpool.py", line 495, in _make_request
    conn.request(
  File "/home/renner/special/mac0499-prototype/venv/lib/python3.12/site-packages/urllib3/connection.py", line 398, in request
    self.endheaders()
  File "/usr/lib/python3.12/http/client.py", line 1331, in endheaders
    self._send_output(message_body, encode_chunked=encode_chunked)
  File "/usr/lib/python3.12/http/client.py", line 1091, in _send_output
    self.send(msg)
  File "/usr/lib/python3.12/http/client.py", line 1035, in send
    self.connect()
  File "/home/renner/special/mac0499-prototype/venv/lib/python3.12/site-packages/urllib3/connection.py", line 236, in connect
    self.sock = self._new_conn()
                ^^^^^^^^^^^^^^^^
  File "/home/renner/special/mac0499-prototype/venv/lib/python3.12/site-packages/urllib3/contrib/socks.py", line 141, in _new_conn
    raise NewConnectionError(
urllib3.exceptions.NewConnectionError: <urllib3.contrib.socks.SOCKSConnection object at 0x75bb2e15faa0>: Failed to establish a new connection: [Errno 111] Connection refused

The above exception was the direct cause of the following exception:

Traceback (most recent call last):
  File "/home/renner/special/mac0499-prototype/venv/lib/python3.12/site-packages/requests/adapters.py", line 667, in send
    resp = conn.urlopen(
           ^^^^^^^^^^^^^
  File "/home/renner/special/mac0499-prototype/venv/lib/python3.12/site-packages/urllib3/connectionpool.py", line 843, in urlopen
    retries = retries.increment(
              ^^^^^^^^^^^^^^^^^^
  File "/home/renner/special/mac0499-prototype/venv/lib/python3.12/site-packages/urllib3/util/retry.py", line 519, in increment
    raise MaxRetryError(_pool, url, reason) from reason  # type: ignore[arg-type]
    ^^^^^^^^^^^^^^^^^^^^^^^^^^^^^^^^^^^^^^^^^^^^^^^^^^^
urllib3.exceptions.MaxRetryError: SOCKSHTTPConnectionPool(host='mkl2b3hxadsfza2k3u554s5w6hpth2zgkakbd5ydern6h57dcvggbiyd.onion', port=80): Max retries exceeded with url: /receiveMessage (Caused by NewConnectionError('<urllib3.contrib.socks.SOCKSConnection object at 0x75bb2e15faa0>: Failed to establish a new connection: [Errno 111] Connection refused'))

During handling of the above exception, another exception occurred:

Traceback (most recent call last):
  File "/home/renner/special/mac0499-prototype/venv/lib/python3.12/site-packages/flask/app.py", line 1473, in wsgi_app
    response = self.full_dispatch_request()
               ^^^^^^^^^^^^^^^^^^^^^^^^^^^^
  File "/home/renner/special/mac0499-prototype/venv/lib/python3.12/site-packages/flask/app.py", line 882, in full_dispatch_request
    rv = self.handle_user_exception(e)
         ^^^^^^^^^^^^^^^^^^^^^^^^^^^^^
  File "/home/renner/special/mac0499-prototype/venv/lib/python3.12/site-packages/flask/app.py", line 880, in full_dispatch_request
    rv = self.dispatch_request()
         ^^^^^^^^^^^^^^^^^^^^^^^
  File "/home/renner/special/mac0499-prototype/venv/lib/python3.12/site-packages/flask/app.py", line 865, in dispatch_request
    return self.ensure_sync(self.view_functions[rule.endpoint])(**view_args)  # type: ignore[no-any-return]
           ^^^^^^^^^^^^^^^^^^^^^^^^^^^^^^^^^^^^^^^^^^^^^^^^^^^^^^^^^^^^^^^^^
  File "/home/renner/special/mac0499-prototype/src/endpoints.py", line 91, in sendMessage
    response = requests.post(f"http://{destination}/receiveMessage", data={"message": packagedMessage}, proxies=proxies)
               ^^^^^^^^^^^^^^^^^^^^^^^^^^^^^^^^^^^^^^^^^^^^^^^^^^^^^^^^^^^^^^^^^^^^^^^^^^^^^^^^^^^^^^^^^^^^^^^^^^^^^^^^^
  File "/home/renner/special/mac0499-prototype/venv/lib/python3.12/site-packages/requests/api.py", line 115, in post
    return request("post", url, data=data, json=json, **kwargs)
           ^^^^^^^^^^^^^^^^^^^^^^^^^^^^^^^^^^^^^^^^^^^^^^^^^^^^
  File "/home/renner/special/mac0499-prototype/venv/lib/python3.12/site-packages/requests/api.py", line 59, in request
    return session.request(method=method, url=url, **kwargs)
           ^^^^^^^^^^^^^^^^^^^^^^^^^^^^^^^^^^^^^^^^^^^^^^^^^
  File "/home/renner/special/mac0499-prototype/venv/lib/python3.12/site-packages/requests/sessions.py", line 589, in request
    resp = self.send(prep, **send_kwargs)
           ^^^^^^^^^^^^^^^^^^^^^^^^^^^^^^
  File "/home/renner/special/mac0499-prototype/venv/lib/python3.12/site-packages/requests/sessions.py", line 703, in send
    r = adapter.send(request, **kwargs)
        ^^^^^^^^^^^^^^^^^^^^^^^^^^^^^^^
  File "/home/renner/special/mac0499-prototype/venv/lib/python3.12/site-packages/requests/adapters.py", line 700, in send
    raise ConnectionError(e, request=request)
requests.exceptions.ConnectionError: SOCKSHTTPConnectionPool(host='mkl2b3hxadsfza2k3u554s5w6hpth2zgkakbd5ydern6h57dcvggbiyd.onion', port=80): Max retries exceeded with url: /receiveMessage (Caused by NewConnectionError('<urllib3.contrib.socks.SOCKSConnection object at 0x75bb2e15faa0>: Failed to establish a new connection: [Errno 111] Connection refused'))
Exception on /sendMessage [POST]
Traceback (most recent call last):
  File "/home/renner/special/mac0499-prototype/venv/lib/python3.12/site-packages/socks.py", line 809, in connect
    negotiate(self, dest_addr, dest_port)
  File "/home/renner/special/mac0499-prototype/venv/lib/python3.12/site-packages/socks.py", line 443, in _negotiate_SOCKS5
    self.proxy_peername, self.proxy_sockname = self._SOCKS5_request(
                                               ^^^^^^^^^^^^^^^^^^^^^
  File "/home/renner/special/mac0499-prototype/venv/lib/python3.12/site-packages/socks.py", line 470, in _SOCKS5_request
    chosen_auth = self._readall(reader, 2)
                  ^^^^^^^^^^^^^^^^^^^^^^^^
  File "/home/renner/special/mac0499-prototype/venv/lib/python3.12/site-packages/socks.py", line 276, in _readall
    d = file.read(count - len(data))
        ^^^^^^^^^^^^^^^^^^^^^^^^^^^^
  File "/usr/lib/python3.12/socket.py", line 720, in readinto
    return self._sock.recv_into(b)
           ^^^^^^^^^^^^^^^^^^^^^^^
ConnectionResetError: [Errno 104] Connection reset by peer

During handling of the above exception, another exception occurred:

Traceback (most recent call last):
  File "/home/renner/special/mac0499-prototype/venv/lib/python3.12/site-packages/urllib3/contrib/socks.py", line 110, in _new_conn
    conn = socks.create_connection(
           ^^^^^^^^^^^^^^^^^^^^^^^^
  File "/home/renner/special/mac0499-prototype/venv/lib/python3.12/site-packages/socks.py", line 209, in create_connection
    raise err
  File "/home/renner/special/mac0499-prototype/venv/lib/python3.12/site-packages/socks.py", line 199, in create_connection
    sock.connect((remote_host, remote_port))
  File "/home/renner/special/mac0499-prototype/venv/lib/python3.12/site-packages/socks.py", line 47, in wrapper
    return function(*args, **kwargs)
           ^^^^^^^^^^^^^^^^^^^^^^^^^
  File "/home/renner/special/mac0499-prototype/venv/lib/python3.12/site-packages/socks.py", line 814, in connect
    raise GeneralProxyError("Socket error", error)
socks.GeneralProxyError: Socket error: [Errno 104] Connection reset by peer

During handling of the above exception, another exception occurred:

Traceback (most recent call last):
  File "/home/renner/special/mac0499-prototype/venv/lib/python3.12/site-packages/urllib3/connectionpool.py", line 789, in urlopen
    response = self._make_request(
               ^^^^^^^^^^^^^^^^^^^
  File "/home/renner/special/mac0499-prototype/venv/lib/python3.12/site-packages/urllib3/connectionpool.py", line 495, in _make_request
    conn.request(
  File "/home/renner/special/mac0499-prototype/venv/lib/python3.12/site-packages/urllib3/connection.py", line 398, in request
    self.endheaders()
  File "/usr/lib/python3.12/http/client.py", line 1331, in endheaders
    self._send_output(message_body, encode_chunked=encode_chunked)
  File "/usr/lib/python3.12/http/client.py", line 1091, in _send_output
    self.send(msg)
  File "/usr/lib/python3.12/http/client.py", line 1035, in send
    self.connect()
  File "/home/renner/special/mac0499-prototype/venv/lib/python3.12/site-packages/urllib3/connection.py", line 236, in connect
    self.sock = self._new_conn()
                ^^^^^^^^^^^^^^^^
  File "/home/renner/special/mac0499-prototype/venv/lib/python3.12/site-packages/urllib3/contrib/socks.py", line 141, in _new_conn
    raise NewConnectionError(
urllib3.exceptions.NewConnectionError: <urllib3.contrib.socks.SOCKSConnection object at 0x7e656e6782c0>: Failed to establish a new connection: [Errno 104] Connection reset by peer

The above exception was the direct cause of the following exception:

Traceback (most recent call last):
  File "/home/renner/special/mac0499-prototype/venv/lib/python3.12/site-packages/requests/adapters.py", line 667, in send
    resp = conn.urlopen(
           ^^^^^^^^^^^^^
  File "/home/renner/special/mac0499-prototype/venv/lib/python3.12/site-packages/urllib3/connectionpool.py", line 843, in urlopen
    retries = retries.increment(
              ^^^^^^^^^^^^^^^^^^
  File "/home/renner/special/mac0499-prototype/venv/lib/python3.12/site-packages/urllib3/util/retry.py", line 519, in increment
    raise MaxRetryError(_pool, url, reason) from reason  # type: ignore[arg-type]
    ^^^^^^^^^^^^^^^^^^^^^^^^^^^^^^^^^^^^^^^^^^^^^^^^^^^
urllib3.exceptions.MaxRetryError: SOCKSHTTPConnectionPool(host='mkl2b3hxadsfza2k3u554s5w6hpth2zgkakbd5ydern6h57dcvggbiyd.onion', port=80): Max retries exceeded with url: /receiveMessage (Caused by NewConnectionError('<urllib3.contrib.socks.SOCKSConnection object at 0x7e656e6782c0>: Failed to establish a new connection: [Errno 104] Connection reset by peer'))

During handling of the above exception, another exception occurred:

Traceback (most recent call last):
  File "/home/renner/special/mac0499-prototype/venv/lib/python3.12/site-packages/flask/app.py", line 1473, in wsgi_app
    response = self.full_dispatch_request()
               ^^^^^^^^^^^^^^^^^^^^^^^^^^^^
  File "/home/renner/special/mac0499-prototype/venv/lib/python3.12/site-packages/flask/app.py", line 882, in full_dispatch_request
    rv = self.handle_user_exception(e)
         ^^^^^^^^^^^^^^^^^^^^^^^^^^^^^
  File "/home/renner/special/mac0499-prototype/venv/lib/python3.12/site-packages/flask/app.py", line 880, in full_dispatch_request
    rv = self.dispatch_request()
         ^^^^^^^^^^^^^^^^^^^^^^^
  File "/home/renner/special/mac0499-prototype/venv/lib/python3.12/site-packages/flask/app.py", line 865, in dispatch_request
    return self.ensure_sync(self.view_functions[rule.endpoint])(**view_args)  # type: ignore[no-any-return]
           ^^^^^^^^^^^^^^^^^^^^^^^^^^^^^^^^^^^^^^^^^^^^^^^^^^^^^^^^^^^^^^^^^
  File "/home/renner/special/mac0499-prototype/src/endpoints.py", line 95, in sendMessage
    response = requests.post(f"http://{destination}/receiveMessage", data={"message": packagedMessage}, proxies=proxies)
               ^^^^^^^^^^^^^^^^^^^^^^^^^^^^^^^^^^^^^^^^^^^^^^^^^^^^^^^^^^^^^^^^^^^^^^^^^^^^^^^^^^^^^^^^^^^^^^^^^^^^^^^^^
  File "/home/renner/special/mac0499-prototype/venv/lib/python3.12/site-packages/requests/api.py", line 115, in post
    return request("post", url, data=data, json=json, **kwargs)
           ^^^^^^^^^^^^^^^^^^^^^^^^^^^^^^^^^^^^^^^^^^^^^^^^^^^^
  File "/home/renner/special/mac0499-prototype/venv/lib/python3.12/site-packages/requests/api.py", line 59, in request
    return session.request(method=method, url=url, **kwargs)
           ^^^^^^^^^^^^^^^^^^^^^^^^^^^^^^^^^^^^^^^^^^^^^^^^^
  File "/home/renner/special/mac0499-prototype/venv/lib/python3.12/site-packages/requests/sessions.py", line 589, in request
    resp = self.send(prep, **send_kwargs)
           ^^^^^^^^^^^^^^^^^^^^^^^^^^^^^^
  File "/home/renner/special/mac0499-prototype/venv/lib/python3.12/site-packages/requests/sessions.py", line 703, in send
    r = adapter.send(request, **kwargs)
        ^^^^^^^^^^^^^^^^^^^^^^^^^^^^^^^
  File "/home/renner/special/mac0499-prototype/venv/lib/python3.12/site-packages/requests/adapters.py", line 700, in send
    raise ConnectionError(e, request=request)
requests.exceptions.ConnectionError: SOCKSHTTPConnectionPool(host='mkl2b3hxadsfza2k3u554s5w6hpth2zgkakbd5ydern6h57dcvggbiyd.onion', port=80): Max retries exceeded with url: /receiveMessage (Caused by NewConnectionError('<urllib3.contrib.socks.SOCKSConnection object at 0x7e656e6782c0>: Failed to establish a new connection: [Errno 104] Connection reset by peer'))
Exception on /sendMessage [POST]
Traceback (most recent call last):
  File "/home/renner/special/mac0499-prototype/venv/lib/python3.12/site-packages/socks.py", line 787, in connect
    super(socksocket, self).connect(proxy_addr)
ConnectionRefusedError: [Errno 111] Connection refused

During handling of the above exception, another exception occurred:

Traceback (most recent call last):
  File "/home/renner/special/mac0499-prototype/venv/lib/python3.12/site-packages/urllib3/contrib/socks.py", line 110, in _new_conn
    conn = socks.create_connection(
           ^^^^^^^^^^^^^^^^^^^^^^^^
  File "/home/renner/special/mac0499-prototype/venv/lib/python3.12/site-packages/socks.py", line 209, in create_connection
    raise err
  File "/home/renner/special/mac0499-prototype/venv/lib/python3.12/site-packages/socks.py", line 199, in create_connection
    sock.connect((remote_host, remote_port))
  File "/home/renner/special/mac0499-prototype/venv/lib/python3.12/site-packages/socks.py", line 47, in wrapper
    return function(*args, **kwargs)
           ^^^^^^^^^^^^^^^^^^^^^^^^^
  File "/home/renner/special/mac0499-prototype/venv/lib/python3.12/site-packages/socks.py", line 800, in connect
    raise ProxyConnectionError(msg, error)
socks.ProxyConnectionError: Error connecting to SOCKS5 proxy localhost:5878: [Errno 111] Connection refused

During handling of the above exception, another exception occurred:

Traceback (most recent call last):
  File "/home/renner/special/mac0499-prototype/venv/lib/python3.12/site-packages/urllib3/connectionpool.py", line 789, in urlopen
    response = self._make_request(
               ^^^^^^^^^^^^^^^^^^^
  File "/home/renner/special/mac0499-prototype/venv/lib/python3.12/site-packages/urllib3/connectionpool.py", line 495, in _make_request
    conn.request(
  File "/home/renner/special/mac0499-prototype/venv/lib/python3.12/site-packages/urllib3/connection.py", line 398, in request
    self.endheaders()
  File "/usr/lib/python3.12/http/client.py", line 1331, in endheaders
    self._send_output(message_body, encode_chunked=encode_chunked)
  File "/usr/lib/python3.12/http/client.py", line 1091, in _send_output
    self.send(msg)
  File "/usr/lib/python3.12/http/client.py", line 1035, in send
    self.connect()
  File "/home/renner/special/mac0499-prototype/venv/lib/python3.12/site-packages/urllib3/connection.py", line 236, in connect
    self.sock = self._new_conn()
                ^^^^^^^^^^^^^^^^
  File "/home/renner/special/mac0499-prototype/venv/lib/python3.12/site-packages/urllib3/contrib/socks.py", line 141, in _new_conn
    raise NewConnectionError(
urllib3.exceptions.NewConnectionError: <urllib3.contrib.socks.SOCKSConnection object at 0x7fd6b20f5ca0>: Failed to establish a new connection: [Errno 111] Connection refused

The above exception was the direct cause of the following exception:

Traceback (most recent call last):
  File "/home/renner/special/mac0499-prototype/venv/lib/python3.12/site-packages/requests/adapters.py", line 667, in send
    resp = conn.urlopen(
           ^^^^^^^^^^^^^
  File "/home/renner/special/mac0499-prototype/venv/lib/python3.12/site-packages/urllib3/connectionpool.py", line 843, in urlopen
    retries = retries.increment(
              ^^^^^^^^^^^^^^^^^^
  File "/home/renner/special/mac0499-prototype/venv/lib/python3.12/site-packages/urllib3/util/retry.py", line 519, in increment
    raise MaxRetryError(_pool, url, reason) from reason  # type: ignore[arg-type]
    ^^^^^^^^^^^^^^^^^^^^^^^^^^^^^^^^^^^^^^^^^^^^^^^^^^^
urllib3.exceptions.MaxRetryError: SOCKSHTTPConnectionPool(host='bmqk3imjw3ytjejbfj77wjxvxy3dls6r7hdpf42tio7ovlmjlwgt25yd.onion', port=80): Max retries exceeded with url: /receiveMessage (Caused by NewConnectionError('<urllib3.contrib.socks.SOCKSConnection object at 0x7fd6b20f5ca0>: Failed to establish a new connection: [Errno 111] Connection refused'))

During handling of the above exception, another exception occurred:

Traceback (most recent call last):
  File "/home/renner/special/mac0499-prototype/venv/lib/python3.12/site-packages/flask/app.py", line 1473, in wsgi_app
    response = self.full_dispatch_request()
               ^^^^^^^^^^^^^^^^^^^^^^^^^^^^
  File "/home/renner/special/mac0499-prototype/venv/lib/python3.12/site-packages/flask/app.py", line 882, in full_dispatch_request
    rv = self.handle_user_exception(e)
         ^^^^^^^^^^^^^^^^^^^^^^^^^^^^^
  File "/home/renner/special/mac0499-prototype/venv/lib/python3.12/site-packages/flask/app.py", line 880, in full_dispatch_request
    rv = self.dispatch_request()
         ^^^^^^^^^^^^^^^^^^^^^^^
  File "/home/renner/special/mac0499-prototype/venv/lib/python3.12/site-packages/flask/app.py", line 865, in dispatch_request
    return self.ensure_sync(self.view_functions[rule.endpoint])(**view_args)  # type: ignore[no-any-return]
           ^^^^^^^^^^^^^^^^^^^^^^^^^^^^^^^^^^^^^^^^^^^^^^^^^^^^^^^^^^^^^^^^^
  File "/home/renner/special/mac0499-prototype/src/endpoints.py", line 95, in sendMessage
    response = requests.post(f"http://{destination}/receiveMessage", data={"message": packagedMessage}, proxies=proxies)
               ^^^^^^^^^^^^^^^^^^^^^^^^^^^^^^^^^^^^^^^^^^^^^^^^^^^^^^^^^^^^^^^^^^^^^^^^^^^^^^^^^^^^^^^^^^^^^^^^^^^^^^^^^
  File "/home/renner/special/mac0499-prototype/venv/lib/python3.12/site-packages/requests/api.py", line 115, in post
    return request("post", url, data=data, json=json, **kwargs)
           ^^^^^^^^^^^^^^^^^^^^^^^^^^^^^^^^^^^^^^^^^^^^^^^^^^^^
  File "/home/renner/special/mac0499-prototype/venv/lib/python3.12/site-packages/requests/api.py", line 59, in request
    return session.request(method=method, url=url, **kwargs)
           ^^^^^^^^^^^^^^^^^^^^^^^^^^^^^^^^^^^^^^^^^^^^^^^^^
  File "/home/renner/special/mac0499-prototype/venv/lib/python3.12/site-packages/requests/sessions.py", line 589, in request
    resp = self.send(prep, **send_kwargs)
           ^^^^^^^^^^^^^^^^^^^^^^^^^^^^^^
  File "/home/renner/special/mac0499-prototype/venv/lib/python3.12/site-packages/requests/sessions.py", line 703, in send
    r = adapter.send(request, **kwargs)
        ^^^^^^^^^^^^^^^^^^^^^^^^^^^^^^^
  File "/home/renner/special/mac0499-prototype/venv/lib/python3.12/site-packages/requests/adapters.py", line 700, in send
    raise ConnectionError(e, request=request)
requests.exceptions.ConnectionError: SOCKSHTTPConnectionPool(host='bmqk3imjw3ytjejbfj77wjxvxy3dls6r7hdpf42tio7ovlmjlwgt25yd.onion', port=80): Max retries exceeded with url: /receiveMessage (Caused by NewConnectionError('<urllib3.contrib.socks.SOCKSConnection object at 0x7fd6b20f5ca0>: Failed to establish a new connection: [Errno 111] Connection refused'))
Exception on /getMessagesFromSender [POST]
Traceback (most recent call last):
  File "/home/renner/special/mac0499-prototype/venv/lib/python3.12/site-packages/flask/app.py", line 1473, in wsgi_app
    response = self.full_dispatch_request()
               ^^^^^^^^^^^^^^^^^^^^^^^^^^^^
  File "/home/renner/special/mac0499-prototype/venv/lib/python3.12/site-packages/flask/app.py", line 882, in full_dispatch_request
    rv = self.handle_user_exception(e)
         ^^^^^^^^^^^^^^^^^^^^^^^^^^^^^
  File "/home/renner/special/mac0499-prototype/venv/lib/python3.12/site-packages/flask/app.py", line 880, in full_dispatch_request
    rv = self.dispatch_request()
         ^^^^^^^^^^^^^^^^^^^^^^^
  File "/home/renner/special/mac0499-prototype/venv/lib/python3.12/site-packages/flask/app.py", line 865, in dispatch_request
    return self.ensure_sync(self.view_functions[rule.endpoint])(**view_args)  # type: ignore[no-any-return]
           ^^^^^^^^^^^^^^^^^^^^^^^^^^^^^^^^^^^^^^^^^^^^^^^^^^^^^^^^^^^^^^^^^
  File "/home/renner/special/mac0499-prototype/src/endpoints.py", line 168, in getMessagesFromSender
    console.log(response)
    ^^^^^^^
NameError: name 'console' is not defined
Exception on /getMessagesFromSender [POST]
Traceback (most recent call last):
  File "/home/renner/special/mac0499-prototype/venv/lib/python3.12/site-packages/flask/app.py", line 1473, in wsgi_app
    response = self.full_dispatch_request()
               ^^^^^^^^^^^^^^^^^^^^^^^^^^^^
  File "/home/renner/special/mac0499-prototype/venv/lib/python3.12/site-packages/flask/app.py", line 882, in full_dispatch_request
    rv = self.handle_user_exception(e)
         ^^^^^^^^^^^^^^^^^^^^^^^^^^^^^
  File "/home/renner/special/mac0499-prototype/venv/lib/python3.12/site-packages/flask/app.py", line 880, in full_dispatch_request
    rv = self.dispatch_request()
         ^^^^^^^^^^^^^^^^^^^^^^^
  File "/home/renner/special/mac0499-prototype/venv/lib/python3.12/site-packages/flask/app.py", line 865, in dispatch_request
    return self.ensure_sync(self.view_functions[rule.endpoint])(**view_args)  # type: ignore[no-any-return]
           ^^^^^^^^^^^^^^^^^^^^^^^^^^^^^^^^^^^^^^^^^^^^^^^^^^^^^^^^^^^^^^^^^
  File "/home/renner/special/mac0499-prototype/src/endpoints.py", line 168, in getMessagesFromSender
    console.log(response)
    ^^^^^^^
NameError: name 'console' is not defined
Exception on /sendMessage [POST]
Traceback (most recent call last):
  File "/home/renner/special/mac0499-prototype/venv/lib/python3.12/site-packages/socks.py", line 787, in connect
    super(socksocket, self).connect(proxy_addr)
ConnectionRefusedError: [Errno 111] Connection refused

During handling of the above exception, another exception occurred:

Traceback (most recent call last):
  File "/home/renner/special/mac0499-prototype/venv/lib/python3.12/site-packages/urllib3/contrib/socks.py", line 110, in _new_conn
    conn = socks.create_connection(
           ^^^^^^^^^^^^^^^^^^^^^^^^
  File "/home/renner/special/mac0499-prototype/venv/lib/python3.12/site-packages/socks.py", line 209, in create_connection
    raise err
  File "/home/renner/special/mac0499-prototype/venv/lib/python3.12/site-packages/socks.py", line 199, in create_connection
    sock.connect((remote_host, remote_port))
  File "/home/renner/special/mac0499-prototype/venv/lib/python3.12/site-packages/socks.py", line 47, in wrapper
    return function(*args, **kwargs)
           ^^^^^^^^^^^^^^^^^^^^^^^^^
  File "/home/renner/special/mac0499-prototype/venv/lib/python3.12/site-packages/socks.py", line 800, in connect
    raise ProxyConnectionError(msg, error)
socks.ProxyConnectionError: Error connecting to SOCKS5 proxy localhost:5878: [Errno 111] Connection refused

During handling of the above exception, another exception occurred:

Traceback (most recent call last):
  File "/home/renner/special/mac0499-prototype/venv/lib/python3.12/site-packages/urllib3/connectionpool.py", line 789, in urlopen
    response = self._make_request(
               ^^^^^^^^^^^^^^^^^^^
  File "/home/renner/special/mac0499-prototype/venv/lib/python3.12/site-packages/urllib3/connectionpool.py", line 495, in _make_request
    conn.request(
  File "/home/renner/special/mac0499-prototype/venv/lib/python3.12/site-packages/urllib3/connection.py", line 398, in request
    self.endheaders()
  File "/usr/lib/python3.12/http/client.py", line 1331, in endheaders
    self._send_output(message_body, encode_chunked=encode_chunked)
  File "/usr/lib/python3.12/http/client.py", line 1091, in _send_output
    self.send(msg)
  File "/usr/lib/python3.12/http/client.py", line 1035, in send
    self.connect()
  File "/home/renner/special/mac0499-prototype/venv/lib/python3.12/site-packages/urllib3/connection.py", line 236, in connect
    self.sock = self._new_conn()
                ^^^^^^^^^^^^^^^^
  File "/home/renner/special/mac0499-prototype/venv/lib/python3.12/site-packages/urllib3/contrib/socks.py", line 141, in _new_conn
    raise NewConnectionError(
urllib3.exceptions.NewConnectionError: <urllib3.contrib.socks.SOCKSConnection object at 0x704a52722000>: Failed to establish a new connection: [Errno 111] Connection refused

The above exception was the direct cause of the following exception:

Traceback (most recent call last):
  File "/home/renner/special/mac0499-prototype/venv/lib/python3.12/site-packages/requests/adapters.py", line 667, in send
    resp = conn.urlopen(
           ^^^^^^^^^^^^^
  File "/home/renner/special/mac0499-prototype/venv/lib/python3.12/site-packages/urllib3/connectionpool.py", line 843, in urlopen
    retries = retries.increment(
              ^^^^^^^^^^^^^^^^^^
  File "/home/renner/special/mac0499-prototype/venv/lib/python3.12/site-packages/urllib3/util/retry.py", line 519, in increment
    raise MaxRetryError(_pool, url, reason) from reason  # type: ignore[arg-type]
    ^^^^^^^^^^^^^^^^^^^^^^^^^^^^^^^^^^^^^^^^^^^^^^^^^^^
urllib3.exceptions.MaxRetryError: SOCKSHTTPConnectionPool(host='bmqk3imjw3ytjejbfj77wjxvxy3dls6r7hdpf42tio7ovlmjlwgt25yd.onion', port=80): Max retries exceeded with url: /receiveMessage (Caused by NewConnectionError('<urllib3.contrib.socks.SOCKSConnection object at 0x704a52722000>: Failed to establish a new connection: [Errno 111] Connection refused'))

During handling of the above exception, another exception occurred:

Traceback (most recent call last):
  File "/home/renner/special/mac0499-prototype/venv/lib/python3.12/site-packages/flask/app.py", line 1473, in wsgi_app
    response = self.full_dispatch_request()
               ^^^^^^^^^^^^^^^^^^^^^^^^^^^^
  File "/home/renner/special/mac0499-prototype/venv/lib/python3.12/site-packages/flask/app.py", line 882, in full_dispatch_request
    rv = self.handle_user_exception(e)
         ^^^^^^^^^^^^^^^^^^^^^^^^^^^^^
  File "/home/renner/special/mac0499-prototype/venv/lib/python3.12/site-packages/flask/app.py", line 880, in full_dispatch_request
    rv = self.dispatch_request()
         ^^^^^^^^^^^^^^^^^^^^^^^
  File "/home/renner/special/mac0499-prototype/venv/lib/python3.12/site-packages/flask/app.py", line 865, in dispatch_request
    return self.ensure_sync(self.view_functions[rule.endpoint])(**view_args)  # type: ignore[no-any-return]
           ^^^^^^^^^^^^^^^^^^^^^^^^^^^^^^^^^^^^^^^^^^^^^^^^^^^^^^^^^^^^^^^^^
  File "/home/renner/special/mac0499-prototype/src/endpoints.py", line 95, in sendMessage
    response = requests.post(f"http://{destination}/receiveMessage", data={"message": packagedMessage}, proxies=proxies)
               ^^^^^^^^^^^^^^^^^^^^^^^^^^^^^^^^^^^^^^^^^^^^^^^^^^^^^^^^^^^^^^^^^^^^^^^^^^^^^^^^^^^^^^^^^^^^^^^^^^^^^^^^^
  File "/home/renner/special/mac0499-prototype/venv/lib/python3.12/site-packages/requests/api.py", line 115, in post
    return request("post", url, data=data, json=json, **kwargs)
           ^^^^^^^^^^^^^^^^^^^^^^^^^^^^^^^^^^^^^^^^^^^^^^^^^^^^
  File "/home/renner/special/mac0499-prototype/venv/lib/python3.12/site-packages/requests/api.py", line 59, in request
    return session.request(method=method, url=url, **kwargs)
           ^^^^^^^^^^^^^^^^^^^^^^^^^^^^^^^^^^^^^^^^^^^^^^^^^
  File "/home/renner/special/mac0499-prototype/venv/lib/python3.12/site-packages/requests/sessions.py", line 589, in request
    resp = self.send(prep, **send_kwargs)
           ^^^^^^^^^^^^^^^^^^^^^^^^^^^^^^
  File "/home/renner/special/mac0499-prototype/venv/lib/python3.12/site-packages/requests/sessions.py", line 703, in send
    r = adapter.send(request, **kwargs)
        ^^^^^^^^^^^^^^^^^^^^^^^^^^^^^^^
  File "/home/renner/special/mac0499-prototype/venv/lib/python3.12/site-packages/requests/adapters.py", line 700, in send
    raise ConnectionError(e, request=request)
requests.exceptions.ConnectionError: SOCKSHTTPConnectionPool(host='bmqk3imjw3ytjejbfj77wjxvxy3dls6r7hdpf42tio7ovlmjlwgt25yd.onion', port=80): Max retries exceeded with url: /receiveMessage (Caused by NewConnectionError('<urllib3.contrib.socks.SOCKSConnection object at 0x704a52722000>: Failed to establish a new connection: [Errno 111] Connection refused'))
Exception on /sendMessage [POST]
Traceback (most recent call last):
  File "/home/renner/special/mac0499-prototype/venv/lib/python3.12/site-packages/socks.py", line 787, in connect
    super(socksocket, self).connect(proxy_addr)
ConnectionRefusedError: [Errno 111] Connection refused

During handling of the above exception, another exception occurred:

Traceback (most recent call last):
  File "/home/renner/special/mac0499-prototype/venv/lib/python3.12/site-packages/urllib3/contrib/socks.py", line 110, in _new_conn
    conn = socks.create_connection(
           ^^^^^^^^^^^^^^^^^^^^^^^^
  File "/home/renner/special/mac0499-prototype/venv/lib/python3.12/site-packages/socks.py", line 209, in create_connection
    raise err
  File "/home/renner/special/mac0499-prototype/venv/lib/python3.12/site-packages/socks.py", line 199, in create_connection
    sock.connect((remote_host, remote_port))
  File "/home/renner/special/mac0499-prototype/venv/lib/python3.12/site-packages/socks.py", line 47, in wrapper
    return function(*args, **kwargs)
           ^^^^^^^^^^^^^^^^^^^^^^^^^
  File "/home/renner/special/mac0499-prototype/venv/lib/python3.12/site-packages/socks.py", line 800, in connect
    raise ProxyConnectionError(msg, error)
socks.ProxyConnectionError: Error connecting to SOCKS5 proxy localhost:5878: [Errno 111] Connection refused

During handling of the above exception, another exception occurred:

Traceback (most recent call last):
  File "/home/renner/special/mac0499-prototype/venv/lib/python3.12/site-packages/urllib3/connectionpool.py", line 789, in urlopen
    response = self._make_request(
               ^^^^^^^^^^^^^^^^^^^
  File "/home/renner/special/mac0499-prototype/venv/lib/python3.12/site-packages/urllib3/connectionpool.py", line 495, in _make_request
    conn.request(
  File "/home/renner/special/mac0499-prototype/venv/lib/python3.12/site-packages/urllib3/connection.py", line 398, in request
    self.endheaders()
  File "/usr/lib/python3.12/http/client.py", line 1331, in endheaders
    self._send_output(message_body, encode_chunked=encode_chunked)
  File "/usr/lib/python3.12/http/client.py", line 1091, in _send_output
    self.send(msg)
  File "/usr/lib/python3.12/http/client.py", line 1035, in send
    self.connect()
  File "/home/renner/special/mac0499-prototype/venv/lib/python3.12/site-packages/urllib3/connection.py", line 236, in connect
    self.sock = self._new_conn()
                ^^^^^^^^^^^^^^^^
  File "/home/renner/special/mac0499-prototype/venv/lib/python3.12/site-packages/urllib3/contrib/socks.py", line 141, in _new_conn
    raise NewConnectionError(
urllib3.exceptions.NewConnectionError: <urllib3.contrib.socks.SOCKSConnection object at 0x7bb62df731d0>: Failed to establish a new connection: [Errno 111] Connection refused

The above exception was the direct cause of the following exception:

Traceback (most recent call last):
  File "/home/renner/special/mac0499-prototype/venv/lib/python3.12/site-packages/requests/adapters.py", line 667, in send
    resp = conn.urlopen(
           ^^^^^^^^^^^^^
  File "/home/renner/special/mac0499-prototype/venv/lib/python3.12/site-packages/urllib3/connectionpool.py", line 843, in urlopen
    retries = retries.increment(
              ^^^^^^^^^^^^^^^^^^
  File "/home/renner/special/mac0499-prototype/venv/lib/python3.12/site-packages/urllib3/util/retry.py", line 519, in increment
    raise MaxRetryError(_pool, url, reason) from reason  # type: ignore[arg-type]
    ^^^^^^^^^^^^^^^^^^^^^^^^^^^^^^^^^^^^^^^^^^^^^^^^^^^
urllib3.exceptions.MaxRetryError: SOCKSHTTPConnectionPool(host='k7s7vzvnlzsijkbzeatq2k75d3ov5mq5xupxt3rifouiwquxnbmzcsqd.onion', port=80): Max retries exceeded with url: /receiveMessage (Caused by NewConnectionError('<urllib3.contrib.socks.SOCKSConnection object at 0x7bb62df731d0>: Failed to establish a new connection: [Errno 111] Connection refused'))

During handling of the above exception, another exception occurred:

Traceback (most recent call last):
  File "/home/renner/special/mac0499-prototype/venv/lib/python3.12/site-packages/flask/app.py", line 1473, in wsgi_app
    response = self.full_dispatch_request()
               ^^^^^^^^^^^^^^^^^^^^^^^^^^^^
  File "/home/renner/special/mac0499-prototype/venv/lib/python3.12/site-packages/flask/app.py", line 882, in full_dispatch_request
    rv = self.handle_user_exception(e)
         ^^^^^^^^^^^^^^^^^^^^^^^^^^^^^
  File "/home/renner/special/mac0499-prototype/venv/lib/python3.12/site-packages/flask/app.py", line 880, in full_dispatch_request
    rv = self.dispatch_request()
         ^^^^^^^^^^^^^^^^^^^^^^^
  File "/home/renner/special/mac0499-prototype/venv/lib/python3.12/site-packages/flask/app.py", line 865, in dispatch_request
    return self.ensure_sync(self.view_functions[rule.endpoint])(**view_args)  # type: ignore[no-any-return]
           ^^^^^^^^^^^^^^^^^^^^^^^^^^^^^^^^^^^^^^^^^^^^^^^^^^^^^^^^^^^^^^^^^
  File "/home/renner/special/mac0499-prototype/src/endpoints.py", line 95, in sendMessage
    response = requests.post(f"http://{destination}/receiveMessage", data={"message": packagedMessage}, proxies=proxies)
               ^^^^^^^^^^^^^^^^^^^^^^^^^^^^^^^^^^^^^^^^^^^^^^^^^^^^^^^^^^^^^^^^^^^^^^^^^^^^^^^^^^^^^^^^^^^^^^^^^^^^^^^^^
  File "/home/renner/special/mac0499-prototype/venv/lib/python3.12/site-packages/requests/api.py", line 115, in post
    return request("post", url, data=data, json=json, **kwargs)
           ^^^^^^^^^^^^^^^^^^^^^^^^^^^^^^^^^^^^^^^^^^^^^^^^^^^^
  File "/home/renner/special/mac0499-prototype/venv/lib/python3.12/site-packages/requests/api.py", line 59, in request
    return session.request(method=method, url=url, **kwargs)
           ^^^^^^^^^^^^^^^^^^^^^^^^^^^^^^^^^^^^^^^^^^^^^^^^^
  File "/home/renner/special/mac0499-prototype/venv/lib/python3.12/site-packages/requests/sessions.py", line 589, in request
    resp = self.send(prep, **send_kwargs)
           ^^^^^^^^^^^^^^^^^^^^^^^^^^^^^^
  File "/home/renner/special/mac0499-prototype/venv/lib/python3.12/site-packages/requests/sessions.py", line 703, in send
    r = adapter.send(request, **kwargs)
        ^^^^^^^^^^^^^^^^^^^^^^^^^^^^^^^
  File "/home/renner/special/mac0499-prototype/venv/lib/python3.12/site-packages/requests/adapters.py", line 700, in send
    raise ConnectionError(e, request=request)
requests.exceptions.ConnectionError: SOCKSHTTPConnectionPool(host='k7s7vzvnlzsijkbzeatq2k75d3ov5mq5xupxt3rifouiwquxnbmzcsqd.onion', port=80): Max retries exceeded with url: /receiveMessage (Caused by NewConnectionError('<urllib3.contrib.socks.SOCKSConnection object at 0x7bb62df731d0>: Failed to establish a new connection: [Errno 111] Connection refused'))
